Traceback (most recent call last):
  File "/Users/dt/venv/gis/lib/python3.8/site-packages/jupyter_cache/executors/utils.py", line 51, in single_nb_execution
    executenb(
  File "/Users/dt/venv/gis/lib/python3.8/site-packages/nbclient/client.py", line 1204, in execute
    return NotebookClient(nb=nb, resources=resources, km=km, **kwargs).execute()
  File "/Users/dt/venv/gis/lib/python3.8/site-packages/nbclient/util.py", line 84, in wrapped
    return just_run(coro(*args, **kwargs))
  File "/Users/dt/venv/gis/lib/python3.8/site-packages/nbclient/util.py", line 62, in just_run
    return loop.run_until_complete(coro)
  File "/Users/dt/miniconda/lib/python3.8/asyncio/base_events.py", line 616, in run_until_complete
    return future.result()
  File "/Users/dt/venv/gis/lib/python3.8/site-packages/nbclient/client.py", line 663, in async_execute
    await self.async_execute_cell(
  File "/Users/dt/venv/gis/lib/python3.8/site-packages/nbclient/client.py", line 965, in async_execute_cell
    await self._check_raise_for_error(cell, cell_index, exec_reply)
  File "/Users/dt/venv/gis/lib/python3.8/site-packages/nbclient/client.py", line 862, in _check_raise_for_error
    raise CellExecutionError.from_cell_and_msg(cell, exec_reply_content)
nbclient.exceptions.CellExecutionError: An error occurred while executing the following cell:
------------------
# Instantiate connection

engine = create_engine(POSTGRES)
connection = engine.connect()
------------------

[0;31m---------------------------------------------------------------------------[0m
[0;31mAttributeError[0m                            Traceback (most recent call last)
Cell [0;32mIn [3], line 3[0m
[1;32m      1[0m [38;5;66;03m# Instantiate connection[39;00m
[0;32m----> 3[0m engine [38;5;241m=[39m [43mcreate_engine[49m[43m([49m[43mPOSTGRES[49m[43m)[49m
[1;32m      4[0m connection [38;5;241m=[39m engine[38;5;241m.[39mconnect()

File [0;32m<string>:2[0m, in [0;36mcreate_engine[0;34m(url, **kwargs)[0m

File [0;32m~/venv/gis/lib/python3.8/site-packages/sqlalchemy/util/deprecations.py:309[0m, in [0;36mdeprecated_params.<locals>.decorate.<locals>.warned[0;34m(fn, *args, **kwargs)[0m
[1;32m    302[0m     [38;5;28;01mif[39;00m m [38;5;129;01min[39;00m kwargs:
[1;32m    303[0m         _warn_with_version(
[1;32m    304[0m             messages[m],
[1;32m    305[0m             versions[m],
[1;32m    306[0m             version_warnings[m],
[1;32m    307[0m             stacklevel[38;5;241m=[39m[38;5;241m3[39m,
[1;32m    308[0m         )
[0;32m--> 309[0m [38;5;28;01mreturn[39;00m [43mfn[49m[43m([49m[38;5;241;43m*[39;49m[43margs[49m[43m,[49m[43m [49m[38;5;241;43m*[39;49m[38;5;241;43m*[39;49m[43mkwargs[49m[43m)[49m

File [0;32m~/venv/gis/lib/python3.8/site-packages/sqlalchemy/engine/create.py:520[0m, in [0;36mcreate_engine[0;34m(url, **kwargs)[0m
[1;32m    517[0m [38;5;66;03m# create url.URL object[39;00m
[1;32m    518[0m u [38;5;241m=[39m _url[38;5;241m.[39mmake_url(url)
[0;32m--> 520[0m u, plugins, kwargs [38;5;241m=[39m [43mu[49m[38;5;241;43m.[39;49m[43m_instantiate_plugins[49m(kwargs)
[1;32m    522[0m entrypoint [38;5;241m=[39m u[38;5;241m.[39m_get_entrypoint()
[1;32m    523[0m dialect_cls [38;5;241m=[39m entrypoint[38;5;241m.[39mget_dialect_cls(u)

[0;31mAttributeError[0m: 'NoneType' object has no attribute '_instantiate_plugins'
AttributeError: 'NoneType' object has no attribute '_instantiate_plugins'

